### Promise.resolve
Promise的静态方法, 可以理解为new Promise()的resolve状态的快捷方式

promise.resolve方法的另一个作用是将`thenable`对象转换成Promise对象


### Promise.reject
Promise的静态方法, 也是new Promise()的reject状态的快捷方式


### 为什么promise只能使用异步调用?

问题的本质在于 接收回调函数的函数, 会根据具体的执行情况, 可以选择同步或者异步的方式对回调函数进行调用. 导致可能会存在同步调用和异步调用同时存在的混乱, 处理顺序会和预期的不符.
因此对Promise规定只能使用异步的方式调用.


### Promise链式调用

- 1. promise chain 中使用 Returen 返回值传递给下一个 task, promise.then不仅是注册一个回调函数, 它还会将回调函数的返回值进行变换, 创建并返回一个promise对象
```js
案例:
var aPromise = new Promise(function (resolve) { resolve(100); }); aPromise.then(function (value) { return value * 2; }); 
aPromise.then(function (value) { return value * 2; }); 
aPromise.then(function (value) { console.log("1: " + value); 

```
- 2. promise.catch()其实就是 promise.then(undefined, onRejected)的一个别名

### Promise与数组
#### Promise.all
- promise.all接受一个都是 Promise的数组, 当所有promise都变成resolve或者reject时, 才去调用.then方法
- promise.all里的 promise在运行时, 并不是顺序执行的, 而是同时开始, 并行执行
- promise.all中的 promise数组里 只要有一个promise返回reject, 就会走到.catch()方法里, 并返回这个Onreject函数
- 如果出现及时存在返回存在reject的情况, 依旧能返回所有的promise结果, 需要外包裹一层promise, 让结果都返回
```js
const wrapPromise = (promise) => {
	return new Promise((resolve, reject) => {
		promise
		.then((info)=> resolve({isok: true, info}))
		.catch((err) => reject({isok: false, err}))
	})
}

const resArr = Promise.all([
	wrapPromise(promise1)
	wrapPromise(promise2)
	wrapPromise(promise3)
])

const [res1, res2, res3] = resArr.map((item) => {
	if (item.isok === true) {
		return item.info
	} else {
		console.log(item.err)
		return {}
	}
})

```
 

#### Promise.race
- Promise.race接受一个 都是 Promise对象的数组, 其中只要有一个Promise对象先变成resolve或者reject时, 就调用.then来处理这个Promise的状态
- Promise.rece中当一个Promise改变状态后, 并不会取消其他Promise继续执行.

### then 和 catch
- .catch相当于 .then(undefined, onRejected).
- 但实际上使用.catch优于 .then(undefined, onRejectd), 因为当存在 .then(resolve, rejected)中走入 resove里发生错误时,  reject是没法捕获的. 但是使用 .then(resolve).catch(err)则可以
1.  使用`promise.then(onFulfilled, onRejected)` 的话
    -   在 `onFulfilled` 中发生异常的话，在 `onRejected` 中是捕获不到这个异常的。
2.  在 `promise.then(onFulfilled).catch(onRejected)` 的情况下
    -   `then` 中产生的异常能在 `.catch` 中捕获
3.  [`.then`](http://liubin.org/promises-book/#promise.then) 和 [`.catch`](http://liubin.org/promises-book/#promise.catch) 在本质上是没有区别的
    -   需要分场合使用。
